<?xml version="1.0" ?>
<!-- =================================================================================== -->
<!-- |    This document was autogenerated by xacro from robot3.urdf.xacro              | -->
<!-- |    EDITING THIS FILE BY HAND IS NOT RECOMMENDED                                 | -->
<!-- =================================================================================== -->
<robot name="Self_Balancing_Robot" xmlns:xacro="http://ros.org/wiki/xacro">
  <sdf version="1.4"/>
  <link name="base_footprint">
    <visual>
      <origin rpy="0 0 0" xyz="0 0 0"/>
      <geometry>
        <box size="0.001 0.001 0.001"/>
      </geometry>
    </visual>
  </link>
  <joint name="base_link_joint" type="fixed">
    <origin rpy="0 0 0" xyz="0 0 0.001"/>
    <parent link="base_footprint"/>
    <child link="Chassis"/>
  </joint>
  <link name="Chassis">
    <inertial>
      <origin rpy="0 0 0" xyz="0.0375 0 0"/>
      <mass value="0.388"/>
      <inertia ixx="0.0113" ixy="0" ixz="0" iyy=".01094" iyz="0" izz=".00971"/>
    </inertial>
    <collision>
      <geometry>
        <box size="0.075 0.175 0.157"/>
        <!-- 0.075 0.175 0.157 -->
      </geometry>
      <origin rpy="0 0 0" xyz="0 0 0"/>
    </collision>
    <visual>
      <geometry>
        <!--<box size = "0.075 0.175 0.157"/> -->
        <mesh filename="package://self_balancing_robot/meshes/Assem_No_wheel.dae" scale="0.001 0.001 0.001"/>
        <!--<mesh filename ="package://self_balancing_robot/meshes/Assem2_No_Wheel.STL"/>-->
      </geometry>
      <origin rpy="0 0 0" xyz="-0.05 -0.090 -.157"/>
    </visual>
  </link>
  <link name="Right_Wheel">
    <inertial>
      <origin rpy="0 0 0" xyz="0.0 0.0185 0"/>
      <mass value="0.03770"/>
      <inertia ixx="0.000096758" ixy="0.0" ixz="0.0" iyy="0.000068429" iyz="0.0000" izz="0.000096758"/>
    </inertial>
    <collision>
      <geometry>
        <cylinder length="0.037" radius="0.0316"/>
      </geometry>
      <origin rpy="1.5708 0 0" xyz="0 0.0150 0"/>
      <!-- Previous <origin rpy = "0 0 0" xyz = "-0.0135 0.0150 -0.0785"/> -->
      <!--
			<origin rpy = "0 0 0" xyz = "0 0.1100 0.0316"/> -->
    </collision>
    <visual>
      <geometry>
        <cylinder length="0.037" radius="0.0316"/>
      </geometry>
      <origin rpy="1.5708 0 0" xyz="0 0.0150 0"/>
      <!-- Previous <origin rpy = "0 0 0" xyz = "-0.0135 0.0150 -0.0785"/> -->
    </visual>
  </link>
  <joint name="Right_wheel_Joint" type="continuous">
    <parent link="base_footprint"/>
    <child link="Right_Wheel"/>
    <origin rpy="0 0 0.0" xyz="-0.0135 0.0875 -0.0785"/>
    <limit effort="100000" velocity="100000"/>
    <axis xyz="0 1 0"/>
  </joint>
  <link name="Left_Wheel">
    <inertial>
      <origin rpy="0 0 0" xyz="0.0 0.0185 0"/>
      <mass value="0.03770"/>
      <inertia ixx="0.000096758" ixy="0.0" ixz="0.0" iyy="0.000068429" iyz="0.0000" izz="0.000096758"/>
    </inertial>
    <collision>
      <geometry>
        <cylinder length="0.037" radius="0.0316"/>
      </geometry>
      <origin rpy="1.5708 0 0" xyz="0 -0.015 0"/>
      <!-- <origin rpy = "0 0 0" xyz = "-0.016 -0.015 -0.0785"/> -->
    </collision>
    <visual>
      <geometry>
        <cylinder length="0.037" radius="0.0316"/>
      </geometry>
      <origin rpy="1.5708 0 0" xyz="0 -0.015 0"/>
      <!-- <origin rpy = "0 0 0" xyz = "-0.016 -0.015 -0.0785"/> -->
    </visual>
  </link>
  <joint name="Left_wheel_Joint" type="continuous">
    <parent link="base_footprint"/>
    <child link="Left_Wheel"/>
    <origin rpy="0 0 0.0" xyz="-0.016 -0.0875 -0.0785"/>
    <limit effort="100000" velocity="100000"/>
    <axis xyz="0 1 0"/>
  </joint>
  <!--fdfjdsf-->
  <gazebo>
    <plugin filename="libgazebo_ros_planar_move.so" name="object_controller">
      <commandTopic>cmd_vel2</commandTopic>
      <odometryTopic>odom</odometryTopic>
      <odometryFrame>odom</odometryFrame>
      <odometryRate>20.0</odometryRate>
      <robotBaseFrame>base_footprint</robotBaseFrame>
    </plugin>
  </gazebo>
  <gazebo reference="Left_Wheel">
    <mu1>0.90</mu1>
    <mu2>0.65</mu2>
    <kp>1000</kp>
    <kd>10</kd>
    <material>Gazebo/Black</material>
  </gazebo>
  <gazebo reference="Right_Wheel">
    <mu1>0.90</mu1>
    <mu2>0.65</mu2>
    <kp>1000</kp>
    <kd>10</kd>
    <material>Gazebo/Black</material>
  </gazebo>
  <gazebo>
    <plugin filename="libgazebo_ros_diff_drive.so" name="differential_drive_controller">
      <legacyMode>false</legacyMode>
      <alwaysOn>true</alwaysOn>
      <updateRate>10</updateRate>
      <leftJoint>Left_wheel_Joint</leftJoint>
      <rightJoint>Right_wheel_Joint</rightJoint>
      <wheelSeparation>0.175</wheelSeparation>
      <wheelDiameter>0.0632</wheelDiameter>
      <torque>10</torque>
      <commandTopic>cmd_vel</commandTopic>
      <odometryTopic>odom</odometryTopic>
      <odometryFrame>odom</odometryFrame>
      <robotBaseFrame>base_footprint</robotBaseFrame>
    </plugin>
  </gazebo>
  <gazebo>
    <plugin filename="libgazebo_ros_imu.so" name="imu_plugin">
      <alwaysOn>true</alwaysOn>
      <bodyName>Chassis</bodyName>
      <topicName>imu</topicName>
      <serviceName>imu_service</serviceName>
      <gaussianNoise>0.0</gaussianNoise>
      <rpyOffsets>0 0 0</rpyOffsets>
      <accelDrift>0.5 0.5 0.5</accelDrift>
      <accelGaussianNoise>0.35 0.35 0.3</accelGaussianNoise>
      <rateDrift>0.0 0.0 0.0</rateDrift>
      <rateGaussianNoise>0.00 0.00 0.00</rateGaussianNoise>
      <headingDrift>0.0</headingDrift>
      <headingGaussianNoise>0.00</headingGaussianNoise>
      <updateRate>00</updateRate>
    </plugin>
  </gazebo>
  <!--<gazebo>
		<plugin name="quadrotor_imu_sim" filename="libhector_gazebo_ros_imu.so">
        <alwaysOn>true</alwaysOn>
        <updateRate>100.0</updateRate>
        <bodyName>base_footprint</bodyName>
        <frameId>ardrone_base_link</frameId>
        <topicName>/ardrone/imu</topicName>
        <rpyOffsets>0 0 0</rpyOffsets> 
        <gaussianNoise>0</gaussianNoise> 
        <accelDrift>0.5 0.5 0.5</accelDrift>
        <accelGaussianNoise>0.35 0.35 0.3</accelGaussianNoise>
        <rateDrift>0.0 0.0 0.0</rateDrift>
        <rateGaussianNoise>0.00 0.00 0.00</rateGaussianNoise>
        <headingDrift>0.0</headingDrift>
        <headingGaussianNoise>0.00</headingGaussianNoise>
      </plugin>
  </gazebo> -->
</robot>
